Traceback (most recent call last):
  File "c:\users\vikram\pokemon_ai\showdown_ai\showdown.py", line 192, in run
    self.play_game(challenge=challenge)
  File "c:\users\vikram\pokemon_ai\showdown_ai\showdown.py", line 174, in play_game
    self.update_latest_turn(gamestate)
  File "c:\users\vikram\pokemon_ai\showdown_ai\showdown.py", line 118, in update_latest_turn
    self.simulator.append_log(gamestate, turns[-1], my_poke=my_poke, opp_poke=opp_poke)
  File "c:\users\vikram\pokemon_ai\showdown_ai\simulator.py", line 22, in append_log
    self.handle_event(gamestate, event)
  File "c:\users\vikram\pokemon_ai\showdown_ai\simulator.py", line 91, in handle_event
    team.set_primary(team.poke_list.index(poke))
ValueError: None is not in list
