Traceback (most recent call last):
  File "c:\users\vikram\pokemon_ai\showdown_ai\showdown.py", line 250, in run
    self.play_game(challenge=challenge)
  File "c:\users\vikram\pokemon_ai\showdown_ai\showdown.py", line 214, in play_game
    gamestate = self.create_initial_gamestate()
  File "c:\users\vikram\pokemon_ai\showdown_ai\showdown.py", line 92, in create_initial_gamestate
    moves = [x[0] for x in poke.predict_moves([])]
  File "c:\users\vikram\pokemon_ai\showdown_ai\team.py", line 203, in predict_moves
    return self.predictor(known_moves)
  File "c:\users\vikram\pokemon_ai\showdown_ai\move_predict.py", line 14, in __call__
    return self.get_moves(*args)
  File "c:\users\vikram\pokemon_ai\showdown_ai\move_predict.py", line 111, in get_moves
    probs = self.get_freqs(poke, self.freq)
  File "c:\users\vikram\pokemon_ai\showdown_ai\move_predict.py", line 136, in get_freqs
    total = float(sum(freq[poke].values()))
KeyError: 'Zoroark'
